Workbook

Sheet INPUT
B2: NO. Reg | E2: : | F2: 432/DKP/VIII/2026
B3: Tanggal. Reg | E3: : | F3: 46265
B4: Hari Nikah | E4: : | F4: Sabtu
B5: Tanggal Nikah | E5: : | F5: 46284
B6: Jam | E6: :
B7: Tempat akad | E7: : | F7: Jln.Tembakau
B8: Maskawin | E8: :
B10: DATA PENGANTIN | K10: DATA ORANG TUA | S10: DATA PENGANTIN
B11: LAKI-LAKI | K11: I. | L11: BAPAK | S11: CALON ISTRI
B12: 1 | C12: Nama lengkap dan alias | H12: : | I12: Muh.Israh | K12: 1 | L12: Nama lengkap dan alias | P12: : | Q12: Djahuddin, SE.Sy | S12: 1 | T12: Nama lengkap dan alias | X12: : | Y12: Niken Johanni Syufitri.J
B13: 2 | C13: Bin | H13: : | I13: Djahuddin | K13: 2 | L13: Bin | P13: : | Q13: Ku Lang | S13: 2 | T13: Binti | X13: : | Y13: Ali Johan
B14: 3 | C14: Jenis Kelamin | H14: : | I14: Laki-Laki | K14: 3 | L14: Tempat dan tanggal lahir | P14: : | Q14: Buntulu, 21 Januari 1973 | S14: 3 | T14: Tempat dan tanggal lahir | X14: : | Y14: Jeneponto, 01 Juli 2000
B15: 4 | C15: Tempat dan tanggal lahir | H15: : | I15: Jeneponto, 28 Februari 1998 | K15: 4 | L15: Nomor Induk Kependudukan (NIK) | P15: : | Q15: 7304092101730001 | S15: 4 | T15: Nomor Induk Kependudukan (NIK) | X15: : | Y15: 7304034107000016
B16: 5 | C16: Nomor Induk Kependudukan (NIK) | H16: : | I16: 7304092802980001 | K16: 5 | L16: Warga Negara | P16: : | Q16: Indonesia | S16: 5 | T16: Warga Negara | X16: : | Y16: Indonesia
B17: 6 | C17: Warga Negara | H17: : | I17: Indonesia | K17: 6 | L17: Agama | P17: : | Q17: Islam | S17: 6 | T17: Agama | X17: : | Y17: Islam
B18: 7 | C18: Agama | H18: : | I18: Islam | K18: 7 | L18: Pendidikan | P18: : | Q18: SLTA/Sederajat | S18: 7 | T18: Pendidikan | X18: : | Y18: Diploma IV/Strata I
B19: 8 | C19: Pendidikan | H19: : | I19: SLTA/Sederajat | K19: 8 | L19: Pekerjaan | P19: : | Q19: PNS | S19: 8 | T19: Pekerjaan | X19: : | Y19: Belum/Tidak Bekerja
B20: 9 | C20: Pekerjaan | H20: : | I20: Pelajar/Mahasiswa | K20: 9 | L20: Tempat tinggal | P20: : | Q20: Buntulu Desa Kampala | S20: 9 | T20: Tempat tinggal | X20: : | Y20: Jl. Tembakau No.4 Bontosunggu Desa/Kelurahan Empoang Kec.Binamu
B21: 10 | C21: Tempat tinggal | H21: : | I21: Buntulu Desa Kampala
B22: 11 | C22: Status perkawinan | K22: II. | L22: IBU
C23: a. | D23: Jika Pria, terangkan jejaka, | K23: 1 | L23: Nama lengkap dan alias | P23: : | Q23: Sukmawati | S23: KETERANGAN KEMATIAN
D24: duda atau beristri dan | K24: 2 | L24: Binti | P24: : | Q24: Nusi | S24: ISTRI
D25: berapa isterinya. | H25: : | I25: Perjaka | K25: 3 | L25: Tempat dan tanggal lahir | P25: : | Q25: Borong Bilalang | S25: 1 | T25: Nama lengkap dan alias | X25: :
C26: b. | D26: Jika wanita, terangkan | K26: 4 | L26: Nomor Induk Kependudukan (NIK) | P26: : | Q26: 7304094107750008 | S26: 2 | T26: Bin/Binti | X26: :
D27: perawan atau janda | H27: : | I27: -- | K27: 5 | L27: Warga Negara | P27: : | Q27: Indonesia | S27: 3 | T27: Tempat dan tanggal lahir | X27: :
B28: 12 | C28: Nama isteri/suami terdahulu | H28: : | K28: 6 | L28: Agama | P28: : | Q28: Islam | S28: 4 | T28: Nomor Induk Kependudukan (NIK) | X28: :
K29: 7 | L29: Pendidikan | P29: : | Q29: Sukmawati | S29: 5 | T29: Warga Negara | X29: :
K30: 8 | L30: Pekerjaan | P30: : | Q30: IRT | S30: 6 | T30: Agama | X30: :
K31: 9 | L31: Tempat tinggal | P31: : | Q31: Buntulu Desa Kampala | S31: 7 | T31: Pendidikan | X31: :
S32: 8 | T32: Pekerjaan | X32: :
S33: 9 | T33: Tempat tinggal | X33: :
S34: - | T34: telah meninggal dunia pada tanggal | X34: :
S35: - | T35: di | X35: :

Sheet N1
C2: LAMPIRAN V
C3: KEPUTUSAN DIREKTUR JENDERAL BIMBINGAN MASYARAKAT ISLAM
C4: NOMOR 473 TAHUN 2020
C5: TENTANG
C6: PETUNJUK TEKNIS PELAKSANAAN PENCATATAN PERNIKAHAN
C8: FORMULIR PENGANTAR NIKAH
Q10: Model N-1
C12: KANTOR DESA | H12: : | I12: KAMPALA
C13: KECAMATAN | H13: : | I13: ARUNGKEKE
C14: KABUPATEN | H14: : | I14: JENEPONTO
B16: PENGANTAR NIKAH
I17: Nomor : | K17: =INPUT!F2 -> 432/DKP/VIII/2026
C19: Yang bertanda tangan di bawah ini menjelaskan dengan sesungguhnya bahwa :
D20: 1. | E20: Nama | L20: : | M20: =INPUT!I12 -> Muh.Israh
D21: 2. | E21: Nomor Induk Kependudukan (NIK) | L21: : | M21: =INPUT!I16 -> 7304092802980001
D22: 3. | E22: Jenis Kelamin | L22: : | M22: =INPUT!I14 -> Laki-Laki
D23: 4. | E23: Tempat dan tanggal lahir | L23: : | M23: =INPUT!I15 -> Jeneponto, 28 Februari 1998
D24: 5. | E24: Kewarganegaraan | L24: : | M24: =INPUT!I17 -> Indonesia
D25: 6. | E25: Agama | L25: : | M25: =INPUT!I18 -> Islam
D26: 7. | E26: Pekerjaan | L26: : | M26: =INPUT!I20 -> Pelajar/Mahasiswa
D27: 8. | E27: Alamat | L27: : | M27: =INPUT!I21 -> Buntulu Desa Kampala
D28: 9. | E28: Status perkawinan | L28: :
E29: a. | F29: Laki-Laki : Jejaka, Duda
F30: atau beristeri ke : ………. | L30: : | M30: =INPUT!I25 -> Perjaka
E31: b. | F31: Perempuan : Perawan, Janda | L31: : | M31: =INPUT!I27 -> --
D32: 10. | E32: Nama isteri/suami terdahulu | L32: : | M32: =INPUT!I28 -> 0
C33: Adalah benar-benar anak dari perkawinan seorang pria :
D34: Nama lengkap dan alias | L34: : | M34: =INPUT!Q12 -> Djahuddin, SE.Sy
D35: Nomor Induk Kependudukan (NIK) | L35: : | M35: =INPUT!Q15 -> 7304092101730001
D36: Tempat dan tanggal lahir | L36: : | M36: =INPUT!Q14 -> Buntulu, 21 Januari 1973
D37: Kewarganegaraan | L37: : | M37: =INPUT!Q16 -> Indonesia
D38: Agama | L38: : | M38: =INPUT!Q17 -> Islam
D39: Pekerjaan | L39: : | M39: =INPUT!Q19 -> PNS
D40: Alamat | L40: : | M40: =INPUT!Q20 -> Buntulu Desa Kampala
C41: dengan seorang wanita :
D42: Nama lengkap dan alias | L42: : | M42: =INPUT!Q23 -> Sukmawati
D43: Nomor Induk Kependudukan (NIK) | L43: : | M43: =INPUT!Q26 -> 7304094107750008
D44: Tempat dan tanggal lahir | L44: : | M44: =INPUT!Q25 -> Borong Bilalang
D45: Kewarganegaraan | L45: : | M45: =INPUT!Q27 -> Indonesia
D46: Agama | L46: : | M46: =INPUT!Q28 -> Islam
...

Sheet N2
C2: LAMPIRAN V
C3: KEPUTUSAN DIREKTUR JENDERAL BIMBINGAN MASYARAKAT ISLAM
C4: NOMOR 473 TAHUN 2020
C5: TENTANG
C6: PETUNJUK TEKNIS PELAKSANAAN PENCATATAN PERNIKAHAN
C8: FORMULIR PERMOHONAN KEHENDAK NIKAH
R10: Model N-2
C12: Perihal | E12: : | F12: Permohonan Kehendak Nikah | P12: Kampala | R12: =INPUT!F3 -> 46265
C14: Kepada Yth,
C15: Kepala KUA Kecamatan Arungkeke
C16: Di_ | E16: Tempat
H19: Dengan hormat, kami mengajukan kehendak nikah untuk atas nama :
C20: Calon suami | G20: : | H20: =INPUT!I12 -> Muh.Israh
C21: Calon isteri | G21: : | H21: =INPUT!Y12 -> Niken Johanni Syufitri.J
C22: Hari/Tanggal/Jam | G22: : | H22: =INPUT!F4 -> Sabtu | I22: tanggal, | J22: =INPUT!F5 -> 46284 | M22: Jam | N22: =INPUT!F6 -> 0
C23: Tempat akad nikah | G23: : | H23: =INPUT!Y20 -> Jl. Tembakau No.4 Bontosunggu Desa/Kelurahan Empoang Kec.Binamu
C25: Bersama ini kami lampirkan surat-surat yang diperlukan untuk diperiksa sebagai berikut :
C26: 1. | D26: Surat Pengantar Nikah dari Desa
C27: 2. | D27: Persetujuan Calon Mempelai
C28: 3. | D28: Fotokopi Akte Kelahiran
C29: 4. | D29: Fotokopi KTP
C30: 5. | D30: Fotokopi Kartu Keluarga
C31: 6. | D31: Pas Foto ukuran 2x3 : 4 lembar
C32: 7.
C33: 8.
D35: Demikian permohonan ini kami sampaikan, kiranya dapat diperiksa, dihadiri dan dicatat sesuai
C36: dengan ketentuan peraturan perundang-undangan
C39: Diterima tanggal,………………...
C40: Yang menerima, | O40: Wassalam
C41: Kepala KUA/Penghulu | O41: Pemohon
C46: *) | N46: *)

Sheet N4
B2: LAMPIRAN V
B3: KEPUTUSAN DIREKTUR JENDERAL BIMBINGAN MASYARAKAT ISLAM
B4: NOMOR 473 TAHUN 2020
B5: TENTANG
B6: PETUNJUK TEKNIS PELAKSANAAN PENCATATAN PERNIKAHAN
B8: FORMULIR PERSETUJUAN CALON PENGANTIN
M10: Model N-4
A12: PERSETUJUAN CALON PENGANTIN
B14: Yang bertanda tangan di bawah ini :
B15: A. | C15: Calon Suami
C16: 1. | D16: Nama lengkap dan alias | I16: : | J16: =INPUT!I12 -> Muh.Israh
C17: 2. | D17: Bin | I17: : | J17: =INPUT!I13 -> Djahuddin
C18: 3. | D18: Nomor Induk Kependudukan (NIK) | I18: : | J18: =INPUT!I16 -> 7304092802980001
C19: 4. | D19: Tempat dan tanggal lahir | I19: : | J19: =INPUT!I15 -> Jeneponto, 28 Februari 1998
C20: 5. | D20: Kewarganegaraan | I20: : | J20: =INPUT!I17 -> Indonesia
C21: 6. | D21: Agama | I21: : | J21: =INPUT!I18 -> Islam
C22: 7. | D22: Pekerjaan | I22: : | J22: =INPUT!I20 -> Pelajar/Mahasiswa
C23: 8. | D23: Alamat | I23: : | J23: =INPUT!I21 -> Buntulu Desa Kampala
B25: B. | C25: Calon Istri
C26: 1. | D26: Nama lengkap dan alias | I26: : | J26: =INPUT!Y12 -> Niken Johanni Syufitri.J
C27: 2. | D27: Binti | I27: : | J27: =INPUT!Y13 -> Ali Johan
C28: 3. | D28: Nomor Induk Kependudukan (NIK) | I28: : | J28: =INPUT!Y15 -> 7304034107000016
C29: 4. | D29: Tempat dan tanggal lahir | I29: : | J29: =INPUT!Y14 -> Jeneponto, 01 Juli 2000
C30: 5. | D30: Kewarganegaraan | I30: : | J30: =INPUT!Y16 -> Indonesia
C31: 6. | D31: Agama | I31: : | J31: =INPUT!Y17 -> Islam
C32: 7. | D32: Pekerjaan | I32: : | J32: =INPUT!Y19 -> Belum/Tidak Bekerja
C33: 8. | D33: Tempat tinggal | I33: : | J33: =INPUT!Y20 -> Jl. Tembakau No.4 Bontosunggu Desa/Kelurahan Empoang Kec.Binamu
C35: Menyatakan dengan sesungguhnya bahwa atas dasar sukarela, dengan kesadaran sendiri, tanpa
B36: paksaan dari siapapun juga, setuju untuk melangsungkan pernikahan.
B38: Demikian surat persetujuan ini di buat untuk digunakan seperlunya.
J40: Kampala , | K40: =INPUT!F3 -> 46265
E42: I. Calon Suami | J42: II. Calon Isteri
E46: =J16 -> Muh.Israh | J46: =J26 -> Niken Johanni Syufitri.J

Sheet N5
B2: LAMPIRAN V
B3: KEPUTUSAN DIREKTUR JENDERAL BIMBINGAN MASYARAKAT ISLAM
B4: NOMOR 473 TAHUN 2020
B5: TENTANG
B6: PETUNJUK TEKNIS PELAKSANAAN PENCATATAN PERNIKAHAN
B8: FORMULIR SURAT IZIN ORANG TUA
K10: Model N-4
B12: SURAT IZIN ORANG TUA
B14: Yang bertanda tangan di bawah ini :
B15: A. | C15: 1. | D15: Nama lengkap dan alias | H15: : | I15: =INPUT!Q12 -> Djahuddin, SE.Sy
C16: 2. | D16: Bin | H16: : | I16: =INPUT!Q13 -> Ku Lang
C17: 3. | D17: Nomor Induk Kependudukan (NIK) | H17: : | I17: =INPUT!Q15 -> 7304092101730001
C18: 4. | D18: Tempat dan tanggal lahir | H18: : | I18: =INPUT!Q14 -> Buntulu, 21 Januari 1973
C19: 5. | D19: Kewarganegaraan | H19: : | I19: =INPUT!Q16 -> Indonesia
C20: 6. | D20: Agama | H20: : | I20: =INPUT!Q17 -> Islam
C21: 7. | D21: Pekerjaan | H21: : | I21: =INPUT!Q19 -> PNS
C22: 8. | D22: Tempat tinggal | H22: : | I22: =INPUT!Q20 -> Buntulu Desa Kampala
B24: B. | C24: 1. | D24: Nama lengkap dan alias | H24: : | I24: =INPUT!Q23 -> Sukmawati
C25: 2. | D25: Binti | H25: : | I25: =INPUT!Q24 -> Nusi
C26: 3. | D26: Nomor Induk Kependudukan (NIK) | H26: : | I26: =INPUT!Q26 -> 7304094107750008
C27: 4. | D27: Tempat dan tanggal lahir | H27: : | I27: =INPUT!Q25 -> Borong Bilalang
C28: 5. | D28: Kewarganegaraan | H28: : | I28: =INPUT!Q27 -> Indonesia
C29: 6. | D29: Agama | H29: : | I29: =INPUT!Q28 -> Islam
C30: 7. | D30: Pekerjaan | H30: : | I30: =INPUT!Q30 -> IRT
C31: 8. | D31: Tempat tinggal | H31: : | I31: =INPUT!Q31 -> Buntulu Desa Kampala
B33: Adalah ayah dan ibu kandung/wali/pengampu dari :
C34: 1. | D34: Nama lengkap dan alias | H34: : | I34: =INPUT!I12 -> Muh.Israh
C35: 2. | D35: Bin | H35: : | I35: =INPUT!I13 -> Djahuddin
C36: 3. | D36: Nomor Induk Kependudukan (NIK) | H36: : | I36: =INPUT!I16 -> 7304092802980001
C37: 4. | D37: Tempat dan tanggal lahir | H37: : | I37: =INPUT!I15 -> Jeneponto, 28 Februari 1998
C38: 5. | D38: Kewarganegaraan | H38: : | I38: =INPUT!I17 -> Indonesia
C39: 6. | D39: Agama | H39: : | I39: =INPUT!I18 -> Islam
C40: 7. | D40: Pekerjaan | H40: : | I40: =INPUT!I20 -> Pelajar/Mahasiswa
C41: 8. | D41: Alamat | H41: : | I41: =INPUT!I21 -> Buntulu Desa Kampala
B43: Memberikan izin kepada anak kami untuk melakukan pernikahan dengan :
C44: 1. | D44: Nama lengkap dan alias | H44: : | I44: =INPUT!Y12 -> Niken Johanni Syufitri.J
C45: 2. | D45: Binti | H45: : | I45: =INPUT!Y13 -> Ali Johan
C46: 3. | D46: Nomor Induk Kependudukan (NIK) | H46: : | I46: =INPUT!Y15 -> 7304034107000016
C47: 4. | D47: Tempat dan tanggal lahir | H47: : | I47: =INPUT!Y14 -> Jeneponto, 01 Juli 2000
C48: 5. | D48: Kewarganegaraan | H48: : | I48: =INPUT!Y16 -> Indonesia
...

Sheet Sheet3
